/home/efleisig/.local/lib/python3.10/site-packages/huggingface_hub/file_download.py:1132: FutureWarning: `resume_download` is deprecated and will be removed in version 1.0.0. Downloads always resume when possible. If you want to force a new download, use `force_download=True`.
  warnings.warn(
Traceback (most recent call last):
  File "/home/efleisig/.local/lib/python3.10/site-packages/huggingface_hub/utils/_errors.py", line 304, in hf_raise_for_status
    response.raise_for_status()
  File "/home/efleisig/.local/lib/python3.10/site-packages/requests/models.py", line 1021, in raise_for_status
    raise HTTPError(http_error_msg, response=self)
requests.exceptions.HTTPError: 404 Client Error: Not Found for url: https://huggingface.co/huggingface/llama3-8b/resolve/main/tokenizer_config.json
The above exception was the direct cause of the following exception:
Traceback (most recent call last):
  File "/home/efleisig/.local/lib/python3.10/site-packages/transformers/utils/hub.py", line 385, in cached_file
    resolved_file = hf_hub_download(
  File "/home/efleisig/.local/lib/python3.10/site-packages/huggingface_hub/utils/_validators.py", line 114, in _inner_fn
    return fn(*args, **kwargs)
  File "/home/efleisig/.local/lib/python3.10/site-packages/huggingface_hub/file_download.py", line 1221, in hf_hub_download
    return _hf_hub_download_to_cache_dir(
  File "/home/efleisig/.local/lib/python3.10/site-packages/huggingface_hub/file_download.py", line 1325, in _hf_hub_download_to_cache_dir
    _raise_on_head_call_error(head_call_error, force_download, local_files_only)
  File "/home/efleisig/.local/lib/python3.10/site-packages/huggingface_hub/file_download.py", line 1823, in _raise_on_head_call_error
    raise head_call_error
  File "/home/efleisig/.local/lib/python3.10/site-packages/huggingface_hub/file_download.py", line 1722, in _get_metadata_or_catch_error
    metadata = get_hf_file_metadata(url=url, proxies=proxies, timeout=etag_timeout, headers=headers)
  File "/home/efleisig/.local/lib/python3.10/site-packages/huggingface_hub/utils/_validators.py", line 114, in _inner_fn
    return fn(*args, **kwargs)
  File "/home/efleisig/.local/lib/python3.10/site-packages/huggingface_hub/file_download.py", line 1645, in get_hf_file_metadata
    r = _request_wrapper(
  File "/home/efleisig/.local/lib/python3.10/site-packages/huggingface_hub/file_download.py", line 372, in _request_wrapper
    response = _request_wrapper(
  File "/home/efleisig/.local/lib/python3.10/site-packages/huggingface_hub/file_download.py", line 396, in _request_wrapper
    hf_raise_for_status(response)
  File "/home/efleisig/.local/lib/python3.10/site-packages/huggingface_hub/utils/_errors.py", line 352, in hf_raise_for_status
    raise RepositoryNotFoundError(message, response) from e
huggingface_hub.utils._errors.RepositoryNotFoundError: 404 Client Error. (Request ID: Root=1-666bc518-41be3c7c3fca554e7f479982;1a62767a-38ef-44e5-a160-02f4109bcdcc)
Repository Not Found for url: https://huggingface.co/huggingface/llama3-8b/resolve/main/tokenizer_config.json.
Please make sure you specified the correct `repo_id` and `repo_type`.
If you are trying to access a private or gated repo, make sure you are authenticated.
The above exception was the direct cause of the following exception:
Traceback (most recent call last):
  File "/home/efleisig/sams_reu/llama3_train.py", line 16, in <module>
    tokenizer = LlamaTokenizer.from_pretrained(model_name)
  File "/home/efleisig/.local/lib/python3.10/site-packages/transformers/tokenization_utils_base.py", line 1952, in from_pretrained
    resolved_config_file = cached_file(
  File "/home/efleisig/.local/lib/python3.10/site-packages/transformers/utils/hub.py", line 406, in cached_file
    raise EnvironmentError(
OSError: huggingface/llama3-8b is not a local folder and is not a valid model identifier listed on 'https://huggingface.co/models'
If this is a private repository, make sure to pass a token having permission to this repo either by logging in with `huggingface-cli login` or by passing `token=<your_token>`
Traceback (most recent call last):
  File "/home/efleisig/.local/lib/python3.10/site-packages/huggingface_hub/utils/_errors.py", line 304, in hf_raise_for_status
    response.raise_for_status()
  File "/home/efleisig/.local/lib/python3.10/site-packages/requests/models.py", line 1021, in raise_for_status
    raise HTTPError(http_error_msg, response=self)
requests.exceptions.HTTPError: 404 Client Error: Not Found for url: https://huggingface.co/huggingface/llama3-8b/resolve/main/tokenizer_config.json
The above exception was the direct cause of the following exception:
Traceback (most recent call last):
  File "/home/efleisig/.local/lib/python3.10/site-packages/transformers/utils/hub.py", line 385, in cached_file
    resolved_file = hf_hub_download(
  File "/home/efleisig/.local/lib/python3.10/site-packages/huggingface_hub/utils/_validators.py", line 114, in _inner_fn
    return fn(*args, **kwargs)
  File "/home/efleisig/.local/lib/python3.10/site-packages/huggingface_hub/file_download.py", line 1221, in hf_hub_download
    return _hf_hub_download_to_cache_dir(
  File "/home/efleisig/.local/lib/python3.10/site-packages/huggingface_hub/file_download.py", line 1325, in _hf_hub_download_to_cache_dir
    _raise_on_head_call_error(head_call_error, force_download, local_files_only)
  File "/home/efleisig/.local/lib/python3.10/site-packages/huggingface_hub/file_download.py", line 1823, in _raise_on_head_call_error
    raise head_call_error
  File "/home/efleisig/.local/lib/python3.10/site-packages/huggingface_hub/file_download.py", line 1722, in _get_metadata_or_catch_error
    metadata = get_hf_file_metadata(url=url, proxies=proxies, timeout=etag_timeout, headers=headers)
  File "/home/efleisig/.local/lib/python3.10/site-packages/huggingface_hub/utils/_validators.py", line 114, in _inner_fn
    return fn(*args, **kwargs)
  File "/home/efleisig/.local/lib/python3.10/site-packages/huggingface_hub/file_download.py", line 1645, in get_hf_file_metadata
    r = _request_wrapper(
  File "/home/efleisig/.local/lib/python3.10/site-packages/huggingface_hub/file_download.py", line 372, in _request_wrapper
    response = _request_wrapper(
  File "/home/efleisig/.local/lib/python3.10/site-packages/huggingface_hub/file_download.py", line 396, in _request_wrapper
    hf_raise_for_status(response)
  File "/home/efleisig/.local/lib/python3.10/site-packages/huggingface_hub/utils/_errors.py", line 352, in hf_raise_for_status
    raise RepositoryNotFoundError(message, response) from e
huggingface_hub.utils._errors.RepositoryNotFoundError: 404 Client Error. (Request ID: Root=1-666bc518-41be3c7c3fca554e7f479982;1a62767a-38ef-44e5-a160-02f4109bcdcc)
Repository Not Found for url: https://huggingface.co/huggingface/llama3-8b/resolve/main/tokenizer_config.json.
Please make sure you specified the correct `repo_id` and `repo_type`.
If you are trying to access a private or gated repo, make sure you are authenticated.
The above exception was the direct cause of the following exception:
Traceback (most recent call last):
  File "/home/efleisig/sams_reu/llama3_train.py", line 16, in <module>
    tokenizer = LlamaTokenizer.from_pretrained(model_name)
  File "/home/efleisig/.local/lib/python3.10/site-packages/transformers/tokenization_utils_base.py", line 1952, in from_pretrained
    resolved_config_file = cached_file(
  File "/home/efleisig/.local/lib/python3.10/site-packages/transformers/utils/hub.py", line 406, in cached_file
    raise EnvironmentError(
OSError: huggingface/llama3-8b is not a local folder and is not a valid model identifier listed on 'https://huggingface.co/models'
If this is a private repository, make sure to pass a token having permission to this repo either by logging in with `huggingface-cli login` or by passing `token=<your_token>`